<?xml version="1.0" ?>
<robot name="assembly_urdf"
  xmlns:xacro="http://www.ros.org/wiki/xacro">

  <xacro:property name="joint_damping" value="0.001" />
  <xacro:property name="joint_friction" value="0.61" />

  <!--hand_stiffness to adjust mass, so force from other joint will not disturb other joints-->
  <!--regarding there are some objects that has no inertia value-->
  <xacro:property name="hand_stiffness" value="10" />

  <xacro:include filename="$(find assembly_urdf_description)/urdf/materials.xacro" />
  <xacro:include filename="$(find assembly_urdf_description)/urdf/assembly_urdf.trans" />
  <xacro:include filename="$(find assembly_urdf_description)/urdf/assembly_urdf.gazebo" />

  <xacro:macro name="inertia_macro" params="radius height mass *origin">
    <inertial>
      <mass value="${mass}" />
      <xacro:insert_block name="origin" />
      <inertia ixx="${((1 / 4) * mass * radius * radius) + ((1 / 12) * mass * height * height)}" ixy="0.0" ixz="0.0" iyy="${((1 / 4) * mass * radius * radius) + ((1 / 12) * mass * height * height)}" iyz="0.0" izz="${(1 / 2) * mass * radius * radius}" />
    </inertial>
  </xacro:macro>

  <physics type="ode">
    <gravity xyz="0 0 -9.8"/>
    <ode>
      <constraints cfm="0.0" erp="0.2" contact_max_correcting_vel="0.1" contact_surface_layer="0.001"/>
    </ode>
  </physics>

  <link name="world">
  </link>
  <joint name="base_fixed_joint" type="fixed">
    <parent link="world"/>
    <child link="base_link"/>
  </joint>

  <link name="base_link">
    <xacro:inertia_macro radius="0.0702" height="0.1749" mass="${0.2458664564570096*hand_stiffness}">
      <origin rpy="0 0 0" xyz="0.007413303848346014 0.06187243424866449 0.052543473427993696"/>
    </xacro:inertia_macro>
    <!-- <inertial>
      <origin rpy="0 0 0" xyz="0.007413303848346014 0.06187243424866449 0.052543473427993696"/>
      <mass value="${0.2458664564570096*10}"/>
      <inertia ixx="0.000116" ixy="1e-06" ixz="-7.6e-05" iyy="0.000506" iyz="0.0" izz="0.000541"/>
    </inertial> -->
    <visual>
      <origin rpy="0 0 0" xyz="0 0 0"/>
      <geometry>
        <mesh filename="package://assembly_urdf_description/meshes/base_link.stl" scale="0.001 0.001 0.001"/>
      </geometry>
      <material name="silver_default"/>
    </visual>
    <collision>
      <origin rpy="0 0 0" xyz="0 0 0"/>
      <geometry>
        <mesh filename="package://assembly_urdf_description/meshes/base_link.stl" scale="0.001 0.001 0.001"/>
      </geometry>
    </collision>
  </link>

  <link name="r_rod_a_1">
    <xacro:inertia_macro radius="0.03" height="0.0958" mass="${0.010269254213715277*hand_stiffness}">
      <origin rpy="0 0 0" xyz="-0.020217705524359718 -0.008692491778806266 0.011597193240543216"/>
    </xacro:inertia_macro>
    <visual>
      <origin rpy="0 0 0" xyz="0.0377 -0.047281 -0.081235"/>
      <geometry>
        <mesh filename="package://assembly_urdf_description/meshes/r_rod_a_1.stl" scale="0.001 0.001 0.001"/>
      </geometry>
      <material name="silver_default"/>
    </visual>
    <collision>
      <origin rpy="0 0 0" xyz="0.0377 -0.047281 -0.081235"/>
      <geometry>
        <mesh filename="package://assembly_urdf_description/meshes/r_rod_a_1.stl" scale="0.001 0.001 0.001"/>
      </geometry>
    </collision>
  </link>

  <link name="r_finger_1">
    <inertial>
      <origin rpy="0 0 0" xyz="-0.024119579980588904 -0.001488477039536324 -0.0005708329568233222"/>
      <mass value="0.007495062841070901"/>
      <inertia ixx="0.0" ixy="0.0" ixz="-0.0" iyy="0.0" iyz="0.0" izz="0.0"/>
    </inertial>
    <visual>
      <origin rpy="0 0 0" xyz="0.111195 -0.015682 -0.096135"/>
      <geometry>
        <mesh filename="package://assembly_urdf_description/meshes/r_finger_1.stl" scale="0.001 0.001 0.001"/>
      </geometry>
      <material name="silver_default"/>
    </visual>
    <collision>
      <origin rpy="0 0 0" xyz="0.111195 -0.015682 -0.096135"/>
      <geometry>
        <mesh filename="package://assembly_urdf_description/meshes/r_finger_1.stl" scale="0.001 0.001 0.001"/>
      </geometry>
    </collision>
  </link>

  <link name="r_roll_1">
    <inertial>
      <origin rpy="0 0 0" xyz="9.593091910869989e-06 0.0027691787390397987 -7.722870663945391e-07"/>
      <mass value="0.00146239508937493"/>
      <inertia ixx="0.0" ixy="0.0" ixz="-0.0" iyy="0.0" iyz="0.0" izz="0.0"/>
    </inertial>
    <visual>
      <origin rpy="0 0 0" xyz="0.172173 -0.021897 -0.092985"/>
      <geometry>
        <mesh filename="package://assembly_urdf_description/meshes/r_roll_1.stl" scale="0.001 0.001 0.001"/>
      </geometry>
      <material name="silver_default"/>
    </visual>
    <collision>
      <origin rpy="0 0 0" xyz="0.172173 -0.021897 -0.092985"/>
      <geometry>
        <mesh filename="package://assembly_urdf_description/meshes/r_roll_1.stl" scale="0.001 0.001 0.001"/>
      </geometry>
    </collision>
  </link>

  <link name="r_pinion_1">
    <inertial>
      <origin rpy="0 0 0" xyz="1.5015478240128222e-07 1.5928290141714596e-07 -3.6802972981642146e-07"/>
      <mass value="0.003623475341770341"/>
      <inertia ixx="0.0" ixy="-0.0" ixz="0.0" iyy="0.0" iyz="0.0" izz="0.0"/>
    </inertial>
    <visual>
      <origin rpy="0 0 0" xyz="-0.014852 -0.047596 -0.080135"/>
      <geometry>
        <mesh filename="package://assembly_urdf_description/meshes/r_pinion_1.stl" scale="0.001 0.001 0.001"/>
      </geometry>
      <material name="silver_default"/>
    </visual>
    <collision>
      <origin rpy="0 0 0" xyz="-0.014852 -0.047596 -0.080135"/>
      <geometry>
        <mesh filename="package://assembly_urdf_description/meshes/r_pinion_1.stl" scale="0.001 0.001 0.001"/>
      </geometry>
    </collision>
  </link>

  <link name="l_pinion_1">
    <inertial>
      <origin rpy="0 0 0" xyz="4.768988167459798e-07 -1.730447465875251e-08 -3.702835613822453e-07"/>
      <mass value="0.003623475341770341"/>
      <inertia ixx="0.0" ixy="0.0" ixz="0.0" iyy="0.0" iyz="0.0" izz="0.0"/>
    </inertial>
    <visual>
      <origin rpy="0 0 0" xyz="-0.014952 -0.076096 -0.080135"/>
      <geometry>
        <mesh filename="package://assembly_urdf_description/meshes/l_pinion_1.stl" scale="0.001 0.001 0.001"/>
      </geometry>
      <material name="silver_default"/>
    </visual>
    <collision>
      <origin rpy="0 0 0" xyz="-0.014952 -0.076096 -0.080135"/>
      <geometry>
        <mesh filename="package://assembly_urdf_description/meshes/l_pinion_1.stl" scale="0.001 0.001 0.001"/>
      </geometry>
    </collision>
  </link>

  <link name="l_hand_1">
    <inertial>
      <origin rpy="0 0 0" xyz="0.07733247742865593 0.0010803267326356947 0.02315602960205109"/>
      <mass value="0.10430872211507385"/>
      <inertia ixx="2.7e-05" ixy="-5e-06" ixz="-9e-06" iyy="7.2e-05" iyz="-2e-06" izz="6e-05"/>
    </inertial>
    <visual>
      <origin rpy="0 0 0" xyz="0.095795 -0.076986 -0.041735"/>
      <geometry>
        <mesh filename="package://assembly_urdf_description/meshes/l_hand_1.stl" scale="0.001 0.001 0.001"/>
      </geometry>
      <material name="silver_default"/>
    </visual>
    <collision>
      <origin rpy="0 0 0" xyz="0.095795 -0.076986 -0.041735"/>
      <geometry>
        <mesh filename="package://assembly_urdf_description/meshes/l_hand_1.stl" scale="0.001 0.001 0.001"/>
      </geometry>
    </collision>
  </link>

  <link name="l_rod_a_1">
    <xacro:inertia_macro radius="0.03" height="0.0958" mass="${0.006812361578477563*hand_stiffness}">
      <origin rpy="0 0 0" xyz="-0.03054027136832653 0.012965713261783293 -0.0001934454667376767"/>
    </xacro:inertia_macro>
    <visual>
      <origin rpy="0 0 0" xyz="0.036595 -0.076777 -0.08431"/>
      <geometry>
        <mesh filename="package://assembly_urdf_description/meshes/l_rod_a_1.stl" scale="0.001 0.001 0.001"/>
      </geometry>
      <material name="abs_white"/>
    </visual>
    <collision>
      <origin rpy="0 0 0" xyz="0.036595 -0.076777 -0.08431"/>
      <geometry>
        <mesh filename="package://assembly_urdf_description/meshes/l_rod_a_1.stl" scale="0.001 0.001 0.001"/>
      </geometry>
    </collision>
  </link>

  <link name="r_rod_b_1">
    <xacro:inertia_macro radius="0.03" height="0.091" mass="${0.006019153293969891*hand_stiffness}">
      <origin rpy="0 0 0" xyz="-0.03546590189328162 -0.015248493044195312 0.0005366330930280383"/>
    </xacro:inertia_macro>
    <visual>
      <origin rpy="0 0 0" xyz="0.029748 -0.033397 -0.101735"/>
      <geometry>
        <mesh filename="package://assembly_urdf_description/meshes/r_rod_b_1.stl" scale="0.001 0.001 0.001"/>
      </geometry>
      <material name="silver_default"/>
    </visual>
    <collision>
      <origin rpy="0 0 0" xyz="0.029748 -0.033397 -0.101735"/>
      <geometry>
        <mesh filename="package://assembly_urdf_description/meshes/r_rod_b_1.stl" scale="0.001 0.001 0.001"/>
      </geometry>
    </collision>
  </link>

  <link name="l_roll_1">
    <inertial>
      <origin rpy="0 0 0" xyz="-9.886936053443707e-06 -0.0027936159676818645 -5.458161498328451e-07"/>
      <mass value="0.0015592094271936565"/>
      <inertia ixx="0.0" ixy="0.0" ixz="0.0" iyy="0.0" iyz="-0.0" izz="0.0"/>
    </inertial>
    <visual>
      <origin rpy="0 0 0" xyz="0.169963 -0.09995 -0.09331"/>
      <geometry>
        <mesh filename="package://assembly_urdf_description/meshes/l_roll_1.stl" scale="0.001 0.001 0.001"/>
      </geometry>
      <material name="silver_default"/>
    </visual>
    <collision>
      <origin rpy="0 0 0" xyz="0.169963 -0.09995 -0.09331"/>
      <geometry>
        <mesh filename="package://assembly_urdf_description/meshes/l_roll_1.stl" scale="0.001 0.001 0.001"/>
      </geometry>
    </collision>
  </link>

  <link name="l_finger_1">
    <inertial>
      <origin rpy="0 0 0" xyz="-0.050733434663407684 0.005756198541935431 0.008468737035185164"/>
      <mass value="0.06168673097027164"/>
      <inertia ixx="0.0" ixy="0.0" ixz="0.0" iyy="0.0" iyz="0.0" izz="0.0"/>
    </inertial>
    <visual>
      <origin rpy="0 0 0" xyz="0.110234 -0.10804 -0.08456"/>
      <geometry>
        <mesh filename="package://assembly_urdf_description/meshes/l_finger_1.stl" scale="0.001 0.001 0.001"/>
      </geometry>
      <material name="silver_default"/>
    </visual>
    <collision>
      <origin rpy="0 0 0" xyz="0.110234 -0.10804 -0.08456"/>
      <geometry>
        <mesh filename="package://assembly_urdf_description/meshes/l_finger_1.stl" scale="0.001 0.001 0.001"/>
      </geometry>
    </collision>
  </link>

  <link name="l_rod_b_1">
    <xacro:inertia_macro radius="0.03" height="0.091" mass="${0.006019153293969891*hand_stiffness}">
      <origin rpy="0 0 0" xyz="-0.03553451754999422 0.015085419938293057 0.0008616330930139443"/>
    </xacro:inertia_macro>
    <visual>
      <origin rpy="0 0 0" xyz="0.028547 -0.090606 -0.089835"/>
      <geometry>
        <mesh filename="package://assembly_urdf_description/meshes/l_rod_b_1.stl" scale="0.001 0.001 0.001"/>
      </geometry>
      <material name="silver_default"/>
    </visual>
    <collision>
      <origin rpy="0 0 0" xyz="0.028547 -0.090606 -0.089835"/>
      <geometry>
        <mesh filename="package://assembly_urdf_description/meshes/l_rod_b_1.stl" scale="0.001 0.001 0.001"/>
      </geometry>
    </collision>
  </link>

  <link name="r_hand_1">
    <inertial>
      <origin rpy="0 0 0" xyz="0.031615247843182134 -0.0016727169016351878 0.026801126213624606"/>
      <mass value="0.11780240999045509"/>
      <inertia ixx="4.1e-05" ixy="6e-06" ixz="-1e-05" iyy="8.5e-05" iyz="3e-06" izz="6.2e-05"/>
    </inertial>
    <visual>
      <origin rpy="0 0 0" xyz="0.050899 -0.047328 -0.041735"/>
      <geometry>
        <mesh filename="package://assembly_urdf_description/meshes/r_hand_1.stl" scale="0.001 0.001 0.001"/>
      </geometry>
      <material name="silver_default"/>
    </visual>
    <collision>
      <origin rpy="0 0 0" xyz="0.050899 -0.047328 -0.041735"/>
      <geometry>
        <mesh filename="package://assembly_urdf_description/meshes/r_hand_1.stl" scale="0.001 0.001 0.001"/>
      </geometry>
    </collision>
  </link>

  <joint name="r_hand_rod_a" type="revolute">
    <origin rpy="0 0 0" xyz="0.013199 -4.7e-05 0.0395"/>
    <parent link="r_hand_1"/>
    <child link="r_rod_a_1"/>
    <axis xyz="-0.0 -0.0 -1.0"/>
    <limit velocity="${pi*0.1}" effort="1" lower="${-0.9}" upper="${1.3}" />
    <dynamics damping="${joint_damping}" friction="${joint_friction}" />
    <implicitSpringDamper>True</implicitSpringDamper>
    <springStiffness>True</springStiffness>
  </joint>

  <joint name="r_rod_a_finger" type="revolute">
    <origin rpy="0 0 0" xyz="-0.073495 -0.031599 0.0149"/>
    <parent link="r_rod_a_1"/>
    <child link="r_finger_1"/>
    <axis xyz="0.0 0.0 1.0"/>
    <limit velocity="${pi*0.1}" effort="1" lower="${-0.9}" upper="${1.3}" />
    <dynamics damping="${joint_damping}" friction="${joint_friction}" />
    <implicitSpringDamper>True</implicitSpringDamper>
    <springStiffness>True</springStiffness>
  </joint>
  <xacro:mimic_joint_plugin_gazebo name_prefix="r_rod_a_finger" parent_joint="r_hand_rod_a" mimic_joint="r_rod_a_finger" has_pid="false" multiplier="1.0" max_effort="1" />

  <joint name="r_finger_roll" type="revolute">
    <origin rpy="0 0 0" xyz="-0.060978 0.006215 -0.00315"/>
    <parent link="r_finger_1"/>
    <child link="r_roll_1"/>
    <axis xyz="-0.00352 -0.999994 0.0"/>
    <limit velocity="${pi*0.25}" effort="10.6" lower="${-0.45}" upper="${pi*0.5}" />
    <dynamics damping="${joint_damping}" friction="${joint_friction}" />
    <implicitSpringDamper>True</implicitSpringDamper>
    <springStiffness>True</springStiffness>
  </joint>
  <xacro:mimic_joint_plugin_gazebo name_prefix="r_finger_roll" parent_joint="l_finger_roll" mimic_joint="r_finger_roll" has_pid="false" multiplier="1.0" max_effort="10.6" />

  <joint name="r_base_hand_r" type="revolute">
    <origin rpy="0 0 0" xyz="0.014852 0.047596 0.080135"/>
    <parent link="base_link"/>
    <child link="r_pinion_1"/>
    <axis xyz="0.0 0.0 1.0"/>
    <limit velocity="${pi*0.25}" effort="10.6" lower="${-pi*3.0}" upper="${0.0}" />
    <dynamics damping="${joint_damping}" friction="${joint_friction}" />
    <implicitSpringDamper>True</implicitSpringDamper>
    <springStiffness>True</springStiffness>
  </joint>

  <joint name="l_base_hand_r" type="revolute">
    <origin rpy="0 0 0" xyz="0.014952 0.076096 0.080135"/>
    <parent link="base_link"/>
    <child link="l_pinion_1"/>
    <axis xyz="0.0 0.0 1.0"/>
    <limit velocity="${pi*0.25}" effort="10.6" lower="${0.0}" upper="${pi*3.0}" />
    <implicitSpringDamper>True</implicitSpringDamper>
    <springStiffness>True</springStiffness>
  </joint>

  <joint name="l_base_hand_s" type="prismatic">
    <origin rpy="0 0 0" xyz="-0.095795 0.076986 0.041735"/>
    <parent link="base_link"/>
    <child link="l_hand_1"/>
    <axis xyz="0.999994 -0.00352 -0.0"/>
    <limit effort="10" lower="-9.0" upper="1.0" velocity="${pi*0.5}"/>
    <dynamics damping="${joint_damping}" friction="${joint_friction}" />
  </joint>

  <joint name="l_hand_rod_a" type="revolute">
    <origin rpy="0 0 0" xyz="0.0592 -0.000209 0.042575"/>
    <parent link="l_hand_1"/>
    <child link="l_rod_a_1"/>
    <axis xyz="0.0 0.0 1.0"/>
    <limit velocity="${pi*0.1}" effort="1" lower="${-0.9}" upper="${1.3}" />
    <dynamics damping="${joint_damping}" friction="${joint_friction}" />
    <implicitSpringDamper>True</implicitSpringDamper>
    <springStiffness>True</springStiffness>
  </joint>

  <joint name="r_hand_rod_b" type="revolute">
    <origin rpy="0 0 0" xyz="0.021151 -0.013931 0.06"/>
    <parent link="r_hand_1"/>
    <child link="r_rod_b_1"/>
    <axis xyz="0.0 0.0 1.0"/>
    <limit velocity="${pi*0.1}" effort="1" lower="${-1.2}" upper="${2.0}" />
    <dynamics damping="${joint_damping}" friction="${joint_friction}" />
    <implicitSpringDamper>True</implicitSpringDamper>
    <springStiffness>True</springStiffness>
  </joint>
  <xacro:mimic_joint_plugin_gazebo name_prefix="r_hand_rod_b" parent_joint="r_hand_rod_a" mimic_joint="r_hand_rod_b" has_pid="false" multiplier="-1.0" max_effort="1" />

  <joint name="l_finger_roll" type="revolute">
    <origin rpy="0 0 0" xyz="-0.059729 -0.00809 0.00875"/>
    <parent link="l_finger_1"/>
    <child link="l_roll_1"/>
    <axis xyz="-0.00352 -0.999994 0.0"/>
    <limit velocity="${pi*0.25}" effort="10.6" lower="${-0.45}" upper="${pi*0.5}" />
    <dynamics damping="${joint_damping}" friction="${joint_friction}" />
    <implicitSpringDamper>True</implicitSpringDamper>
    <springStiffness>True</springStiffness>
  </joint>

  <joint name="l_rod_a_finger" type="revolute">
    <origin rpy="0 0 0" xyz="-0.073639 0.031263 0.00025"/>
    <parent link="l_rod_a_1"/>
    <child link="l_finger_1"/>
    <axis xyz="0.0 0.0 1.0"/>
    <limit velocity="${pi*0.1}" effort="1" lower="${-0.9}" upper="${1.3}" />
    <dynamics damping="${joint_damping}" friction="${joint_friction}" />
    <implicitSpringDamper>True</implicitSpringDamper>
    <springStiffness>True</springStiffness>
  </joint>
  <xacro:mimic_joint_plugin_gazebo name_prefix="l_rod_a_finger" parent_joint="l_hand_rod_a" mimic_joint="l_rod_a_finger" has_pid="false" multiplier="-1.0" max_effort="1" />

  <joint name="l_hand_rod_b" type="revolute">
    <origin rpy="0 0 0" xyz="0.067248 0.01362 0.0481"/>
    <parent link="l_hand_1"/>
    <child link="l_rod_b_1"/>
    <axis xyz="0.0 0.0 1.0"/>
    <limit velocity="${pi*0.1}" effort="1" lower="${-1.2}" upper="${2.0}" />
    <dynamics damping="${joint_damping}" friction="${joint_friction}" />
    <implicitSpringDamper>True</implicitSpringDamper>
    <springStiffness>True</springStiffness>
  </joint>
  <xacro:mimic_joint_plugin_gazebo name_prefix="l_hand_rod_b" parent_joint="l_hand_rod_a" mimic_joint="l_hand_rod_b" has_pid="false" multiplier="1.0" max_effort="1" />

  <joint name="r_base_hand_s" type="prismatic">
    <origin rpy="0 0 0" xyz="-0.050899 0.047328 0.041735"/>
    <parent link="base_link"/>
    <child link="r_hand_1"/>
    <axis xyz="0.999994 -0.00352 -0.0"/>
    <limit effort="10" lower="-9.0" upper="1.0" velocity="${pi*0.5}"/>
    <dynamics damping="${joint_damping}" friction="${joint_friction}" />
  </joint>

</robot>
